Microsoft Windows [Version 10.0.19045.4046]
(c) Microsoft Corporation. All rights reserved.

C:\MAJOR PROJ\Adaptive_Hierarchical_Cyber_Attack_Detection\Adaptive_Hierarchical_Cyber_Attack_Detection\adaptive_hierarchical_cyber_attack_detection>python --version
Python 3.6.2

C:\MAJOR PROJ\Adaptive_Hierarchical_Cyber_Attack_Detection\Adaptive_Hierarchical_Cyber_Attack_Detection\adaptive_hierarchical_cyber_attack_detection>python manage.py runserver
Traceback (most recent call last):
  File "manage.py", line 11, in main
    from django.core.management import execute_from_command_line
ModuleNotFoundError: No module named 'django'

The above exception was the direct cause of the following exception:

Traceback (most recent call last):
  File "manage.py", line 22, in <module>
    main()
  File "manage.py", line 17, in main
    ) from exc
ImportError: Couldn't import Django. Are you sure it's installed and available on your PYTHONPATH environment variable? Did you forget to activate a virtual environment?

C:\MAJOR PROJ\Adaptive_Hierarchical_Cyber_Attack_Detection\Adaptive_Hierarchical_Cyber_Attack_Detection\adaptive_hierarchical_cyber_attack_detection>pip install django==2.1.7
Collecting django==2.1.7
  Cache entry deserialization failed, entry ignored
  Downloading https://files.pythonhosted.org/packages/c7/87/fbd666c4f87591ae25b7bb374298e8629816e87193c4099d3608ef11fab9/Django-2.1.7-py3-none-any.whl (7.3MB)
    100% |████████████████████████████████| 7.3MB 122kB/s
Collecting pytz (from django==2.1.7)
  Cache entry deserialization failed, entry ignored
  Downloading https://files.pythonhosted.org/packages/9c/3d/a121f284241f08268b21359bd425f7d4825cffc5ac5cd0e1b3d82ffd2b10/pytz-2024.1-py2.py3-none-any.whl (505kB)
    100% |████████████████████████████████| 512kB 324kB/s
Installing collected packages: pytz, django
Successfully installed django-2.1.7 pytz-2024.1
You are using pip version 9.0.1, however version 24.0 is available.
You should consider upgrading via the 'python -m pip install --upgrade pip' command.

C:\MAJOR PROJ\Adaptive_Hierarchical_Cyber_Attack_Detection\Adaptive_Hierarchical_Cyber_Attack_Detection\adaptive_hierarchical_cyber_attack_detection>python manage.py runserver
Unhandled exception in thread started by <function check_errors.<locals>.wrapper at 0x00000212F22C9EA0>
Traceback (most recent call last):
  File "C:\Users\PHANI\AppData\Local\Programs\Python\Python36\lib\site-packages\django\db\backends\mysql\base.py", line 15, in <module>
    import MySQLdb as Database
ModuleNotFoundError: No module named 'MySQLdb'

The above exception was the direct cause of the following exception:

Traceback (most recent call last):
  File "C:\Users\PHANI\AppData\Local\Programs\Python\Python36\lib\site-packages\django\utils\autoreload.py", line 225, in wrapper
    fn(*args, **kwargs)
  File "C:\Users\PHANI\AppData\Local\Programs\Python\Python36\lib\site-packages\django\core\management\commands\runserver.py", line 109, in inner_run
    autoreload.raise_last_exception()
  File "C:\Users\PHANI\AppData\Local\Programs\Python\Python36\lib\site-packages\django\utils\autoreload.py", line 248, in raise_last_exception
    raise _exception[1]
  File "C:\Users\PHANI\AppData\Local\Programs\Python\Python36\lib\site-packages\django\core\management\__init__.py", line 337, in execute
    autoreload.check_errors(django.setup)()
  File "C:\Users\PHANI\AppData\Local\Programs\Python\Python36\lib\site-packages\django\utils\autoreload.py", line 225, in wrapper
    fn(*args, **kwargs)
  File "C:\Users\PHANI\AppData\Local\Programs\Python\Python36\lib\site-packages\django\__init__.py", line 24, in setup
    apps.populate(settings.INSTALLED_APPS)
  File "C:\Users\PHANI\AppData\Local\Programs\Python\Python36\lib\site-packages\django\apps\registry.py", line 112, in populate
    app_config.import_models()
  File "C:\Users\PHANI\AppData\Local\Programs\Python\Python36\lib\site-packages\django\apps\config.py", line 198, in import_models
    self.models_module = import_module(models_module_name)
  File "C:\Users\PHANI\AppData\Local\Programs\Python\Python36\lib\importlib\__init__.py", line 126, in import_module
    return _bootstrap._gcd_import(name[level:], package, level)
  File "<frozen importlib._bootstrap>", line 978, in _gcd_import
  File "<frozen importlib._bootstrap>", line 961, in _find_and_load
  File "<frozen importlib._bootstrap>", line 950, in _find_and_load_unlocked
  File "<frozen importlib._bootstrap>", line 655, in _load_unlocked
  File "<frozen importlib._bootstrap_external>", line 678, in exec_module
  File "<frozen importlib._bootstrap>", line 205, in _call_with_frames_removed
  File "C:\Users\PHANI\AppData\Local\Programs\Python\Python36\lib\site-packages\django\contrib\auth\models.py", line 2, in <module>
    from django.contrib.auth.base_user import AbstractBaseUser, BaseUserManager
  File "C:\Users\PHANI\AppData\Local\Programs\Python\Python36\lib\site-packages\django\contrib\auth\base_user.py", line 47, in <module>
    class AbstractBaseUser(models.Model):
  File "C:\Users\PHANI\AppData\Local\Programs\Python\Python36\lib\site-packages\django\db\models\base.py", line 101, in __new__
    new_class.add_to_class('_meta', Options(meta, app_label))
  File "C:\Users\PHANI\AppData\Local\Programs\Python\Python36\lib\site-packages\django\db\models\base.py", line 305, in add_to_class
    value.contribute_to_class(cls, name)
  File "C:\Users\PHANI\AppData\Local\Programs\Python\Python36\lib\site-packages\django\db\models\options.py", line 203, in contribute_to_class
    self.db_table = truncate_name(self.db_table, connection.ops.max_name_length())
  File "C:\Users\PHANI\AppData\Local\Programs\Python\Python36\lib\site-packages\django\db\__init__.py", line 33, in __getattr__
    return getattr(connections[DEFAULT_DB_ALIAS], item)
  File "C:\Users\PHANI\AppData\Local\Programs\Python\Python36\lib\site-packages\django\db\utils.py", line 202, in __getitem__
    backend = load_backend(db['ENGINE'])
  File "C:\Users\PHANI\AppData\Local\Programs\Python\Python36\lib\site-packages\django\db\utils.py", line 110, in load_backend
    return import_module('%s.base' % backend_name)
  File "C:\Users\PHANI\AppData\Local\Programs\Python\Python36\lib\importlib\__init__.py", line 126, in import_module
    return _bootstrap._gcd_import(name[level:], package, level)
  File "C:\Users\PHANI\AppData\Local\Programs\Python\Python36\lib\site-packages\django\db\backends\mysql\base.py", line 20, in <module>
    ) from err
django.core.exceptions.ImproperlyConfigured: Error loading MySQLdb module.
Did you install mysqlclient?

C:\MAJOR PROJ\Adaptive_Hierarchical_Cyber_Attack_Detection\Adaptive_Hierarchical_Cyber_Attack_Detection\adaptive_hierarchical_cyber_attack_detection>pip install --only-binary :all: mysqlclient
Collecting mysqlclient
  Downloading https://files.pythonhosted.org/packages/2c/3c/bd285daffea87cb0d1e33a25c78e155a8e6c551419f38a7636c9de136eed/mysqlclient-2.0.3-cp36-cp36m-win_amd64.whl (178kB)
    100% |████████████████████████████████| 184kB 359kB/s
Installing collected packages: mysqlclient
Successfully installed mysqlclient-2.0.3
You are using pip version 9.0.1, however version 24.0 is available.
You should consider upgrading via the 'python -m pip install --upgrade pip' command.

C:\MAJOR PROJ\Adaptive_Hierarchical_Cyber_Attack_Detection\Adaptive_Hierarchical_Cyber_Attack_Detection\adaptive_hierarchical_cyber_attack_detection>python manage.py runserver
Performing system checks...

Unhandled exception in thread started by <function check_errors.<locals>.wrapper at 0x0000020788D20268>
Traceback (most recent call last):
  File "C:\Users\PHANI\AppData\Local\Programs\Python\Python36\lib\site-packages\django\utils\autoreload.py", line 225, in wrapper
    fn(*args, **kwargs)
  File "C:\Users\PHANI\AppData\Local\Programs\Python\Python36\lib\site-packages\django\core\management\commands\runserver.py", line 117, in inner_run
    self.check(display_num_errors=True)
  File "C:\Users\PHANI\AppData\Local\Programs\Python\Python36\lib\site-packages\django\core\management\base.py", line 379, in check
    include_deployment_checks=include_deployment_checks,
  File "C:\Users\PHANI\AppData\Local\Programs\Python\Python36\lib\site-packages\django\core\management\base.py", line 366, in _run_checks
    return checks.run_checks(**kwargs)
  File "C:\Users\PHANI\AppData\Local\Programs\Python\Python36\lib\site-packages\django\core\checks\registry.py", line 71, in run_checks
    new_errors = check(app_configs=app_configs)
  File "C:\Users\PHANI\AppData\Local\Programs\Python\Python36\lib\site-packages\django\core\checks\urls.py", line 13, in check_url_config
    return check_resolver(resolver)
  File "C:\Users\PHANI\AppData\Local\Programs\Python\Python36\lib\site-packages\django\core\checks\urls.py", line 23, in check_resolver
    return check_method()
  File "C:\Users\PHANI\AppData\Local\Programs\Python\Python36\lib\site-packages\django\urls\resolvers.py", line 396, in check
    for pattern in self.url_patterns:
  File "C:\Users\PHANI\AppData\Local\Programs\Python\Python36\lib\site-packages\django\utils\functional.py", line 37, in __get__
    res = instance.__dict__[self.name] = self.func(instance)
  File "C:\Users\PHANI\AppData\Local\Programs\Python\Python36\lib\site-packages\django\urls\resolvers.py", line 533, in url_patterns
    patterns = getattr(self.urlconf_module, "urlpatterns", self.urlconf_module)
  File "C:\Users\PHANI\AppData\Local\Programs\Python\Python36\lib\site-packages\django\utils\functional.py", line 37, in __get__
    res = instance.__dict__[self.name] = self.func(instance)
  File "C:\Users\PHANI\AppData\Local\Programs\Python\Python36\lib\site-packages\django\urls\resolvers.py", line 526, in urlconf_module
    return import_module(self.urlconf_name)
  File "C:\Users\PHANI\AppData\Local\Programs\Python\Python36\lib\importlib\__init__.py", line 126, in import_module
    return _bootstrap._gcd_import(name[level:], package, level)
  File "<frozen importlib._bootstrap>", line 978, in _gcd_import
  File "<frozen importlib._bootstrap>", line 961, in _find_and_load
  File "<frozen importlib._bootstrap>", line 950, in _find_and_load_unlocked
  File "<frozen importlib._bootstrap>", line 655, in _load_unlocked
  File "<frozen importlib._bootstrap_external>", line 678, in exec_module
  File "<frozen importlib._bootstrap>", line 205, in _call_with_frames_removed
  File "C:\MAJOR PROJ\Adaptive_Hierarchical_Cyber_Attack_Detection\Adaptive_Hierarchical_Cyber_Attack_Detection\adaptive_hierarchical_cyber_attack_detection\adaptive_hierarchical_cyber_attack_detection\urls.py", line 18, in <module>
    from Remote_User import views as remoteuser
  File "C:\MAJOR PROJ\Adaptive_Hierarchical_Cyber_Attack_Detection\Adaptive_Hierarchical_Cyber_Attack_Detection\adaptive_hierarchical_cyber_attack_detection\Remote_User\views.py", line 5, in <module>
    import openpyxl
ModuleNotFoundError: No module named 'openpyxl'

C:\MAJOR PROJ\Adaptive_Hierarchical_Cyber_Attack_Detection\Adaptive_Hierarchical_Cyber_Attack_Detection\adaptive_hierarchical_cyber_attack_detection>pip install openpyxl
Collecting openpyxl
  Downloading https://files.pythonhosted.org/packages/6a/94/a59521de836ef0da54aaf50da6c4da8fb4072fb3053fa71f052fd9399e7a/openpyxl-3.1.2-py2.py3-none-any.whl (249kB)
    100% |████████████████████████████████| 256kB 425kB/s
Collecting et-xmlfile (from openpyxl)
  Downloading https://files.pythonhosted.org/packages/96/c2/3dd434b0108730014f1b96fd286040dc3bcb70066346f7e01ec2ac95865f/et_xmlfile-1.1.0-py3-none-any.whl
Installing collected packages: et-xmlfile, openpyxl
Successfully installed et-xmlfile-1.1.0 openpyxl-3.1.2
You are using pip version 9.0.1, however version 24.0 is available.
You should consider upgrading via the 'python -m pip install --upgrade pip' command.

C:\MAJOR PROJ\Adaptive_Hierarchical_Cyber_Attack_Detection\Adaptive_Hierarchical_Cyber_Attack_Detection\adaptive_hierarchical_cyber_attack_detection>python manage.py runserver
Performing system checks...

Unhandled exception in thread started by <function check_errors.<locals>.wrapper at 0x000001B346C59268>
Traceback (most recent call last):
  File "C:\Users\PHANI\AppData\Local\Programs\Python\Python36\lib\site-packages\django\utils\autoreload.py", line 225, in wrapper
    fn(*args, **kwargs)
  File "C:\Users\PHANI\AppData\Local\Programs\Python\Python36\lib\site-packages\django\core\management\commands\runserver.py", line 117, in inner_run
    self.check(display_num_errors=True)
  File "C:\Users\PHANI\AppData\Local\Programs\Python\Python36\lib\site-packages\django\core\management\base.py", line 379, in check
    include_deployment_checks=include_deployment_checks,
  File "C:\Users\PHANI\AppData\Local\Programs\Python\Python36\lib\site-packages\django\core\management\base.py", line 366, in _run_checks
    return checks.run_checks(**kwargs)
  File "C:\Users\PHANI\AppData\Local\Programs\Python\Python36\lib\site-packages\django\core\checks\registry.py", line 71, in run_checks
    new_errors = check(app_configs=app_configs)
  File "C:\Users\PHANI\AppData\Local\Programs\Python\Python36\lib\site-packages\django\core\checks\urls.py", line 13, in check_url_config
    return check_resolver(resolver)
  File "C:\Users\PHANI\AppData\Local\Programs\Python\Python36\lib\site-packages\django\core\checks\urls.py", line 23, in check_resolver
    return check_method()
  File "C:\Users\PHANI\AppData\Local\Programs\Python\Python36\lib\site-packages\django\urls\resolvers.py", line 396, in check
    for pattern in self.url_patterns:
  File "C:\Users\PHANI\AppData\Local\Programs\Python\Python36\lib\site-packages\django\utils\functional.py", line 37, in __get__
    res = instance.__dict__[self.name] = self.func(instance)
  File "C:\Users\PHANI\AppData\Local\Programs\Python\Python36\lib\site-packages\django\urls\resolvers.py", line 533, in url_patterns
    patterns = getattr(self.urlconf_module, "urlpatterns", self.urlconf_module)
  File "C:\Users\PHANI\AppData\Local\Programs\Python\Python36\lib\site-packages\django\utils\functional.py", line 37, in __get__
    res = instance.__dict__[self.name] = self.func(instance)
  File "C:\Users\PHANI\AppData\Local\Programs\Python\Python36\lib\site-packages\django\urls\resolvers.py", line 526, in urlconf_module
    return import_module(self.urlconf_name)
  File "C:\Users\PHANI\AppData\Local\Programs\Python\Python36\lib\importlib\__init__.py", line 126, in import_module
    return _bootstrap._gcd_import(name[level:], package, level)
  File "<frozen importlib._bootstrap>", line 978, in _gcd_import
  File "<frozen importlib._bootstrap>", line 961, in _find_and_load
  File "<frozen importlib._bootstrap>", line 950, in _find_and_load_unlocked
  File "<frozen importlib._bootstrap>", line 655, in _load_unlocked
  File "<frozen importlib._bootstrap_external>", line 678, in exec_module
  File "<frozen importlib._bootstrap>", line 205, in _call_with_frames_removed
  File "C:\MAJOR PROJ\Adaptive_Hierarchical_Cyber_Attack_Detection\Adaptive_Hierarchical_Cyber_Attack_Detection\adaptive_hierarchical_cyber_attack_detection\adaptive_hierarchical_cyber_attack_detection\urls.py", line 18, in <module>
    from Remote_User import views as remoteuser
  File "C:\MAJOR PROJ\Adaptive_Hierarchical_Cyber_Attack_Detection\Adaptive_Hierarchical_Cyber_Attack_Detection\adaptive_hierarchical_cyber_attack_detection\Remote_User\views.py", line 7, in <module>
    import pandas as pd
ModuleNotFoundError: No module named 'pandas'

C:\MAJOR PROJ\Adaptive_Hierarchical_Cyber_Attack_Detection\Adaptive_Hierarchical_Cyber_Attack_Detection\adaptive_hierarchical_cyber_attack_detection>pip install pandas
Collecting pandas
  Downloading https://files.pythonhosted.org/packages/79/87/8bb36bd4ebae147612c73d1bdc1385db7beebb9eb141c4bfefb33f52c87c/pandas-1.1.5-cp36-cp36m-win_amd64.whl (8.7MB)
    100% |████████████████████████████████| 8.7MB 102kB/s
Collecting numpy>=1.15.4 (from pandas)
  Cache entry deserialization failed, entry ignored
  Downloading https://files.pythonhosted.org/packages/ea/bc/da526221bc111857c7ef39c3af670bbcf5e69c247b0d22e51986f6d0c5c2/numpy-1.19.5-cp36-cp36m-win_amd64.whl (13.2MB)
    100% |████████████████████████████████| 13.2MB 63kB/s
Collecting python-dateutil>=2.7.3 (from pandas)
  Cache entry deserialization failed, entry ignored
  Cache entry deserialization failed, entry ignored
  Downloading https://files.pythonhosted.org/packages/36/7a/87837f39d0296e723bb9b62bbb257d0355c7f6128853c78955f57342a56d/python_dateutil-2.8.2-py2.py3-none-any.whl (247kB)
    100% |████████████████████████████████| 256kB 129kB/s
Requirement already satisfied: pytz>=2017.2 in c:\users\phani\appdata\local\programs\python\python36\lib\site-packages (from pandas)
Collecting six>=1.5 (from python-dateutil>=2.7.3->pandas)
  Cache entry deserialization failed, entry ignored
  Cache entry deserialization failed, entry ignored
  Downloading https://files.pythonhosted.org/packages/d9/5a/e7c31adbe875f2abbb91bd84cf2dc52d792b5a01506781dbcf25c91daf11/six-1.16.0-py2.py3-none-any.whl
Installing collected packages: numpy, six, python-dateutil, pandas
Successfully installed numpy-1.19.5 pandas-1.1.5 python-dateutil-2.8.2 six-1.16.0
You are using pip version 9.0.1, however version 24.0 is available.
You should consider upgrading via the 'python -m pip install --upgrade pip' command.

C:\MAJOR PROJ\Adaptive_Hierarchical_Cyber_Attack_Detection\Adaptive_Hierarchical_Cyber_Attack_Detection\adaptive_hierarchical_cyber_attack_detection>python manage.py runserver
Performing system checks...

Unhandled exception in thread started by <function check_errors.<locals>.wrapper at 0x000002140259A268>
Traceback (most recent call last):
  File "C:\Users\PHANI\AppData\Local\Programs\Python\Python36\lib\site-packages\django\utils\autoreload.py", line 225, in wrapper
    fn(*args, **kwargs)
  File "C:\Users\PHANI\AppData\Local\Programs\Python\Python36\lib\site-packages\django\core\management\commands\runserver.py", line 117, in inner_run
    self.check(display_num_errors=True)
  File "C:\Users\PHANI\AppData\Local\Programs\Python\Python36\lib\site-packages\django\core\management\base.py", line 379, in check
    include_deployment_checks=include_deployment_checks,
  File "C:\Users\PHANI\AppData\Local\Programs\Python\Python36\lib\site-packages\django\core\management\base.py", line 366, in _run_checks
    return checks.run_checks(**kwargs)
  File "C:\Users\PHANI\AppData\Local\Programs\Python\Python36\lib\site-packages\django\core\checks\registry.py", line 71, in run_checks
    new_errors = check(app_configs=app_configs)
  File "C:\Users\PHANI\AppData\Local\Programs\Python\Python36\lib\site-packages\django\core\checks\urls.py", line 13, in check_url_config
    return check_resolver(resolver)
  File "C:\Users\PHANI\AppData\Local\Programs\Python\Python36\lib\site-packages\django\core\checks\urls.py", line 23, in check_resolver
    return check_method()
  File "C:\Users\PHANI\AppData\Local\Programs\Python\Python36\lib\site-packages\django\urls\resolvers.py", line 396, in check
    for pattern in self.url_patterns:
  File "C:\Users\PHANI\AppData\Local\Programs\Python\Python36\lib\site-packages\django\utils\functional.py", line 37, in __get__
    res = instance.__dict__[self.name] = self.func(instance)
  File "C:\Users\PHANI\AppData\Local\Programs\Python\Python36\lib\site-packages\django\urls\resolvers.py", line 533, in url_patterns
    patterns = getattr(self.urlconf_module, "urlpatterns", self.urlconf_module)
  File "C:\Users\PHANI\AppData\Local\Programs\Python\Python36\lib\site-packages\django\utils\functional.py", line 37, in __get__
    res = instance.__dict__[self.name] = self.func(instance)
  File "C:\Users\PHANI\AppData\Local\Programs\Python\Python36\lib\site-packages\django\urls\resolvers.py", line 526, in urlconf_module
    return import_module(self.urlconf_name)
  File "C:\Users\PHANI\AppData\Local\Programs\Python\Python36\lib\importlib\__init__.py", line 126, in import_module
    return _bootstrap._gcd_import(name[level:], package, level)
  File "<frozen importlib._bootstrap>", line 978, in _gcd_import
  File "<frozen importlib._bootstrap>", line 961, in _find_and_load
  File "<frozen importlib._bootstrap>", line 950, in _find_and_load_unlocked
  File "<frozen importlib._bootstrap>", line 655, in _load_unlocked
  File "<frozen importlib._bootstrap_external>", line 678, in exec_module
  File "<frozen importlib._bootstrap>", line 205, in _call_with_frames_removed
  File "C:\MAJOR PROJ\Adaptive_Hierarchical_Cyber_Attack_Detection\Adaptive_Hierarchical_Cyber_Attack_Detection\adaptive_hierarchical_cyber_attack_detection\adaptive_hierarchical_cyber_attack_detection\urls.py", line 18, in <module>
    from Remote_User import views as remoteuser
  File "C:\MAJOR PROJ\Adaptive_Hierarchical_Cyber_Attack_Detection\Adaptive_Hierarchical_Cyber_Attack_Detection\adaptive_hierarchical_cyber_attack_detection\Remote_User\views.py", line 9, in <module>
    import matplotlib.pyplot as plt
ModuleNotFoundError: No module named 'matplotlib'

C:\MAJOR PROJ\Adaptive_Hierarchical_Cyber_Attack_Detection\Adaptive_Hierarchical_Cyber_Attack_Detection\adaptive_hierarchical_cyber_attack_detection>pip install matplotlib
Collecting matplotlib
  Cache entry deserialization failed, entry ignored
  Downloading https://files.pythonhosted.org/packages/da/75/7bb16e22aa3f8d23a3afd065a7c933de71b67561c4561cf162fbc5d94221/matplotlib-3.3.4-cp36-cp36m-win_amd64.whl (8.5MB)
    100% |████████████████████████████████| 8.5MB 96kB/s
Requirement already satisfied: numpy>=1.15 in c:\users\phani\appdata\local\programs\python\python36\lib\site-packages (from matplotlib)
Requirement already satisfied: python-dateutil>=2.1 in c:\users\phani\appdata\local\programs\python\python36\lib\site-packages (from matplotlib)
Collecting kiwisolver>=1.0.1 (from matplotlib)
  Cache entry deserialization failed, entry ignored
  Downloading https://files.pythonhosted.org/packages/6e/df/1250c32ab3b532c32a7e47c1cd240faba98f75b1b5150939b10e9bffb758/kiwisolver-1.3.1-cp36-cp36m-win_amd64.whl (51kB)
    100% |████████████████████████████████| 61kB 171kB/s
Collecting pillow>=6.2.0 (from matplotlib)
  Cache entry deserialization failed, entry ignored
  Downloading https://files.pythonhosted.org/packages/8f/10/c8dc9fff37b69b5962b7783ab4835611e83dada453cd9913d82ca2a1321b/Pillow-8.4.0-cp36-cp36m-win_amd64.whl (3.2MB)
    100% |████████████████████████████████| 3.2MB 160kB/s
Collecting cycler>=0.10 (from matplotlib)
  Cache entry deserialization failed, entry ignored
  Downloading https://files.pythonhosted.org/packages/5c/f9/695d6bedebd747e5eb0fe8fad57b72fdf25411273a39791cde838d5a8f51/cycler-0.11.0-py3-none-any.whl
Collecting pyparsing!=2.0.4,!=2.1.2,!=2.1.6,>=2.0.3 (from matplotlib)
  Cache entry deserialization failed, entry ignored
  Downloading https://files.pythonhosted.org/packages/80/c1/23fd82ad3121656b585351aba6c19761926bb0db2ebed9e4ff09a43a3fcc/pyparsing-3.0.7-py3-none-any.whl (98kB)
    100% |████████████████████████████████| 102kB 359kB/s
Requirement already satisfied: six>=1.5 in c:\users\phani\appdata\local\programs\python\python36\lib\site-packages (from python-dateutil>=2.1->matplotlib)
Installing collected packages: kiwisolver, pillow, cycler, pyparsing, matplotlib
Successfully installed cycler-0.11.0 kiwisolver-1.3.1 matplotlib-3.3.4 pillow-8.4.0 pyparsing-3.0.7
You are using pip version 9.0.1, however version 24.0 is available.
You should consider upgrading via the 'python -m pip install --upgrade pip' command.

C:\MAJOR PROJ\Adaptive_Hierarchical_Cyber_Attack_Detection\Adaptive_Hierarchical_Cyber_Attack_Detection\adaptive_hierarchical_cyber_attack_detection>python manage.py runserver
Performing system checks...

Unhandled exception in thread started by <function check_errors.<locals>.wrapper at 0x000001C953D10378>
Traceback (most recent call last):
  File "C:\Users\PHANI\AppData\Local\Programs\Python\Python36\lib\site-packages\django\utils\autoreload.py", line 225, in wrapper
    fn(*args, **kwargs)
  File "C:\Users\PHANI\AppData\Local\Programs\Python\Python36\lib\site-packages\django\core\management\commands\runserver.py", line 117, in inner_run
    self.check(display_num_errors=True)
  File "C:\Users\PHANI\AppData\Local\Programs\Python\Python36\lib\site-packages\django\core\management\base.py", line 379, in check
    include_deployment_checks=include_deployment_checks,
  File "C:\Users\PHANI\AppData\Local\Programs\Python\Python36\lib\site-packages\django\core\management\base.py", line 366, in _run_checks
    return checks.run_checks(**kwargs)
  File "C:\Users\PHANI\AppData\Local\Programs\Python\Python36\lib\site-packages\django\core\checks\registry.py", line 71, in run_checks
    new_errors = check(app_configs=app_configs)
  File "C:\Users\PHANI\AppData\Local\Programs\Python\Python36\lib\site-packages\django\core\checks\urls.py", line 13, in check_url_config
    return check_resolver(resolver)
  File "C:\Users\PHANI\AppData\Local\Programs\Python\Python36\lib\site-packages\django\core\checks\urls.py", line 23, in check_resolver
    return check_method()
  File "C:\Users\PHANI\AppData\Local\Programs\Python\Python36\lib\site-packages\django\urls\resolvers.py", line 396, in check
    for pattern in self.url_patterns:
  File "C:\Users\PHANI\AppData\Local\Programs\Python\Python36\lib\site-packages\django\utils\functional.py", line 37, in __get__
    res = instance.__dict__[self.name] = self.func(instance)
  File "C:\Users\PHANI\AppData\Local\Programs\Python\Python36\lib\site-packages\django\urls\resolvers.py", line 533, in url_patterns
    patterns = getattr(self.urlconf_module, "urlpatterns", self.urlconf_module)
  File "C:\Users\PHANI\AppData\Local\Programs\Python\Python36\lib\site-packages\django\utils\functional.py", line 37, in __get__
    res = instance.__dict__[self.name] = self.func(instance)
  File "C:\Users\PHANI\AppData\Local\Programs\Python\Python36\lib\site-packages\django\urls\resolvers.py", line 526, in urlconf_module
    return import_module(self.urlconf_name)
  File "C:\Users\PHANI\AppData\Local\Programs\Python\Python36\lib\importlib\__init__.py", line 126, in import_module
    return _bootstrap._gcd_import(name[level:], package, level)
  File "<frozen importlib._bootstrap>", line 978, in _gcd_import
  File "<frozen importlib._bootstrap>", line 961, in _find_and_load
  File "<frozen importlib._bootstrap>", line 950, in _find_and_load_unlocked
  File "<frozen importlib._bootstrap>", line 655, in _load_unlocked
  File "<frozen importlib._bootstrap_external>", line 678, in exec_module
  File "<frozen importlib._bootstrap>", line 205, in _call_with_frames_removed
  File "C:\MAJOR PROJ\Adaptive_Hierarchical_Cyber_Attack_Detection\Adaptive_Hierarchical_Cyber_Attack_Detection\adaptive_hierarchical_cyber_attack_detection\adaptive_hierarchical_cyber_attack_detection\urls.py", line 18, in <module>
    from Remote_User import views as remoteuser
  File "C:\MAJOR PROJ\Adaptive_Hierarchical_Cyber_Attack_Detection\Adaptive_Hierarchical_Cyber_Attack_Detection\adaptive_hierarchical_cyber_attack_detection\Remote_User\views.py", line 10, in <module>
    import seaborn as sns
ModuleNotFoundError: No module named 'seaborn'

C:\MAJOR PROJ\Adaptive_Hierarchical_Cyber_Attack_Detection\Adaptive_Hierarchical_Cyber_Attack_Detection\adaptive_hierarchical_cyber_attack_detection>pip install seaborn
Collecting seaborn
  Downloading https://files.pythonhosted.org/packages/10/5b/0479d7d845b5ba410ca702ffcd7f2cd95a14a4dfff1fde2637802b258b9b/seaborn-0.11.2-py3-none-any.whl (292kB)
    100% |████████████████████████████████| 296kB 189kB/s
Collecting scipy>=1.0 (from seaborn)
  Downloading https://files.pythonhosted.org/packages/f3/9f/80522344838ae24cac9e945240436269cbb92349f7f1f4c9dfc10cb6bad5/scipy-1.5.4-cp36-cp36m-win_amd64.whl (31.2MB)
    100% |████████████████████████████████| 31.2MB 30kB/s
Requirement already satisfied: numpy>=1.15 in c:\users\phani\appdata\local\programs\python\python36\lib\site-packages (from seaborn)
Requirement already satisfied: pandas>=0.23 in c:\users\phani\appdata\local\programs\python\python36\lib\site-packages (from seaborn)
Requirement already satisfied: matplotlib>=2.2 in c:\users\phani\appdata\local\programs\python\python36\lib\site-packages (from seaborn)
Requirement already satisfied: python-dateutil>=2.7.3 in c:\users\phani\appdata\local\programs\python\python36\lib\site-packages (from pandas>=0.23->seaborn)
Requirement already satisfied: pytz>=2017.2 in c:\users\phani\appdata\local\programs\python\python36\lib\site-packages (from pandas>=0.23->seaborn)
Requirement already satisfied: pyparsing!=2.0.4,!=2.1.2,!=2.1.6,>=2.0.3 in c:\users\phani\appdata\local\programs\python\python36\lib\site-packages (from matplotlib>=2.2->seaborn)
Requirement already satisfied: cycler>=0.10 in c:\users\phani\appdata\local\programs\python\python36\lib\site-packages (from matplotlib>=2.2->seaborn)
Requirement already satisfied: kiwisolver>=1.0.1 in c:\users\phani\appdata\local\programs\python\python36\lib\site-packages (from matplotlib>=2.2->seaborn)
Requirement already satisfied: pillow>=6.2.0 in c:\users\phani\appdata\local\programs\python\python36\lib\site-packages (from matplotlib>=2.2->seaborn)
Requirement already satisfied: six>=1.5 in c:\users\phani\appdata\local\programs\python\python36\lib\site-packages (from python-dateutil>=2.7.3->pandas>=0.23->seaborn)
Installing collected packages: scipy, seaborn
Successfully installed scipy-1.5.4 seaborn-0.11.2
You are using pip version 9.0.1, however version 24.0 is available.
You should consider upgrading via the 'python -m pip install --upgrade pip' command.

C:\MAJOR PROJ\Adaptive_Hierarchical_Cyber_Attack_Detection\Adaptive_Hierarchical_Cyber_Attack_Detection\adaptive_hierarchical_cyber_attack_detection>python manage.py runserver
Performing system checks...

Unhandled exception in thread started by <function check_errors.<locals>.wrapper at 0x0000026D6E481378>
Traceback (most recent call last):
  File "C:\Users\PHANI\AppData\Local\Programs\Python\Python36\lib\site-packages\django\utils\autoreload.py", line 225, in wrapper
    fn(*args, **kwargs)
  File "C:\Users\PHANI\AppData\Local\Programs\Python\Python36\lib\site-packages\django\core\management\commands\runserver.py", line 117, in inner_run
    self.check(display_num_errors=True)
  File "C:\Users\PHANI\AppData\Local\Programs\Python\Python36\lib\site-packages\django\core\management\base.py", line 379, in check
    include_deployment_checks=include_deployment_checks,
  File "C:\Users\PHANI\AppData\Local\Programs\Python\Python36\lib\site-packages\django\core\management\base.py", line 366, in _run_checks
    return checks.run_checks(**kwargs)
  File "C:\Users\PHANI\AppData\Local\Programs\Python\Python36\lib\site-packages\django\core\checks\registry.py", line 71, in run_checks
    new_errors = check(app_configs=app_configs)
  File "C:\Users\PHANI\AppData\Local\Programs\Python\Python36\lib\site-packages\django\core\checks\urls.py", line 13, in check_url_config
    return check_resolver(resolver)
  File "C:\Users\PHANI\AppData\Local\Programs\Python\Python36\lib\site-packages\django\core\checks\urls.py", line 23, in check_resolver
    return check_method()
  File "C:\Users\PHANI\AppData\Local\Programs\Python\Python36\lib\site-packages\django\urls\resolvers.py", line 396, in check
    for pattern in self.url_patterns:
  File "C:\Users\PHANI\AppData\Local\Programs\Python\Python36\lib\site-packages\django\utils\functional.py", line 37, in __get__
    res = instance.__dict__[self.name] = self.func(instance)
  File "C:\Users\PHANI\AppData\Local\Programs\Python\Python36\lib\site-packages\django\urls\resolvers.py", line 533, in url_patterns
    patterns = getattr(self.urlconf_module, "urlpatterns", self.urlconf_module)
  File "C:\Users\PHANI\AppData\Local\Programs\Python\Python36\lib\site-packages\django\utils\functional.py", line 37, in __get__
    res = instance.__dict__[self.name] = self.func(instance)
  File "C:\Users\PHANI\AppData\Local\Programs\Python\Python36\lib\site-packages\django\urls\resolvers.py", line 526, in urlconf_module
    return import_module(self.urlconf_name)
  File "C:\Users\PHANI\AppData\Local\Programs\Python\Python36\lib\importlib\__init__.py", line 126, in import_module
    return _bootstrap._gcd_import(name[level:], package, level)
  File "<frozen importlib._bootstrap>", line 978, in _gcd_import
  File "<frozen importlib._bootstrap>", line 961, in _find_and_load
  File "<frozen importlib._bootstrap>", line 950, in _find_and_load_unlocked
  File "<frozen importlib._bootstrap>", line 655, in _load_unlocked
  File "<frozen importlib._bootstrap_external>", line 678, in exec_module
  File "<frozen importlib._bootstrap>", line 205, in _call_with_frames_removed
  File "C:\MAJOR PROJ\Adaptive_Hierarchical_Cyber_Attack_Detection\Adaptive_Hierarchical_Cyber_Attack_Detection\adaptive_hierarchical_cyber_attack_detection\adaptive_hierarchical_cyber_attack_detection\urls.py", line 18, in <module>
    from Remote_User import views as remoteuser
  File "C:\MAJOR PROJ\Adaptive_Hierarchical_Cyber_Attack_Detection\Adaptive_Hierarchical_Cyber_Attack_Detection\adaptive_hierarchical_cyber_attack_detection\Remote_User\views.py", line 12, in <module>
    from sklearn.ensemble import VotingClassifier
ModuleNotFoundError: No module named 'sklearn'

C:\MAJOR PROJ\Adaptive_Hierarchical_Cyber_Attack_Detection\Adaptive_Hierarchical_Cyber_Attack_Detection\adaptive_hierarchical_cyber_attack_detection>pip install sklearn-genetic==0.2
Collecting sklearn-genetic==0.2
  Downloading https://files.pythonhosted.org/packages/25/a7/495e10b18fa87d8865fb768c7dc050bbc183bfbbc212f3e612423f74cd16/sklearn-genetic-0.2.tar.gz
Collecting scikit-learn>=0.18 (from sklearn-genetic==0.2)
  Downloading https://files.pythonhosted.org/packages/1e/37/57198cbb6ea88b20f78dc6019296ebf2ada76fa258ad010452f7c91d43f7/scikit_learn-0.24.2-cp36-cp36m-win_amd64.whl (6.8MB)
    100% |████████████████████████████████| 6.8MB 136kB/s
Collecting deap>=1.0.2 (from sklearn-genetic==0.2)
  Downloading https://files.pythonhosted.org/packages/4a/3d/b8bdde9a8add8b07fff482e3ad5e4d14233472a51afbe8e49dfb3b4f3b50/deap-1.4.1-cp36-cp36m-win_amd64.whl (104kB)
    100% |████████████████████████████████| 112kB 263kB/s
Requirement already satisfied: scipy>=0.19.1 in c:\users\phani\appdata\local\programs\python\python36\lib\site-packages (from scikit-learn>=0.18->sklearn-genetic==0.2)
Collecting threadpoolctl>=2.0.0 (from scikit-learn>=0.18->sklearn-genetic==0.2)
  Downloading https://files.pythonhosted.org/packages/61/cf/6e354304bcb9c6413c4e02a747b600061c21d38ba51e7e544ac7bc66aecc/threadpoolctl-3.1.0-py3-none-any.whl
Requirement already satisfied: numpy>=1.13.3 in c:\users\phani\appdata\local\programs\python\python36\lib\site-packages (from scikit-learn>=0.18->sklearn-genetic==0.2)
Collecting joblib>=0.11 (from scikit-learn>=0.18->sklearn-genetic==0.2)
  Downloading https://files.pythonhosted.org/packages/7c/91/d3ba0401e62d7e42816bc7d97b82d19c95c164b3e149a87c0a1c026a735e/joblib-1.1.1-py2.py3-none-any.whl (309kB)
    100% |████████████████████████████████| 317kB 311kB/s
Installing collected packages: threadpoolctl, joblib, scikit-learn, deap, sklearn-genetic
  Running setup.py install for sklearn-genetic ... done
Successfully installed deap-1.4.1 joblib-1.1.1 scikit-learn-0.24.2 sklearn-genetic-0.2 threadpoolctl-3.1.0
You are using pip version 9.0.1, however version 24.0 is available.
You should consider upgrading via the 'python -m pip install --upgrade pip' command.

C:\MAJOR PROJ\Adaptive_Hierarchical_Cyber_Attack_Detection\Adaptive_Hierarchical_Cyber_Attack_Detection\adaptive_hierarchical_cyber_attack_detection>python manage.py runserver
Performing system checks...

Unhandled exception in thread started by <function check_errors.<locals>.wrapper at 0x00000230BBD22378>
Traceback (most recent call last):
  File "C:\Users\PHANI\AppData\Local\Programs\Python\Python36\lib\site-packages\django\utils\autoreload.py", line 225, in wrapper
    fn(*args, **kwargs)
  File "C:\Users\PHANI\AppData\Local\Programs\Python\Python36\lib\site-packages\django\core\management\commands\runserver.py", line 117, in inner_run
    self.check(display_num_errors=True)
  File "C:\Users\PHANI\AppData\Local\Programs\Python\Python36\lib\site-packages\django\core\management\base.py", line 379, in check
    include_deployment_checks=include_deployment_checks,
  File "C:\Users\PHANI\AppData\Local\Programs\Python\Python36\lib\site-packages\django\core\management\base.py", line 366, in _run_checks
    return checks.run_checks(**kwargs)
  File "C:\Users\PHANI\AppData\Local\Programs\Python\Python36\lib\site-packages\django\core\checks\registry.py", line 71, in run_checks
    new_errors = check(app_configs=app_configs)
  File "C:\Users\PHANI\AppData\Local\Programs\Python\Python36\lib\site-packages\django\core\checks\urls.py", line 13, in check_url_config
    return check_resolver(resolver)
  File "C:\Users\PHANI\AppData\Local\Programs\Python\Python36\lib\site-packages\django\core\checks\urls.py", line 23, in check_resolver
    return check_method()
  File "C:\Users\PHANI\AppData\Local\Programs\Python\Python36\lib\site-packages\django\urls\resolvers.py", line 396, in check
    for pattern in self.url_patterns:
  File "C:\Users\PHANI\AppData\Local\Programs\Python\Python36\lib\site-packages\django\utils\functional.py", line 37, in __get__
    res = instance.__dict__[self.name] = self.func(instance)
  File "C:\Users\PHANI\AppData\Local\Programs\Python\Python36\lib\site-packages\django\urls\resolvers.py", line 533, in url_patterns
    patterns = getattr(self.urlconf_module, "urlpatterns", self.urlconf_module)
  File "C:\Users\PHANI\AppData\Local\Programs\Python\Python36\lib\site-packages\django\utils\functional.py", line 37, in __get__
    res = instance.__dict__[self.name] = self.func(instance)
  File "C:\Users\PHANI\AppData\Local\Programs\Python\Python36\lib\site-packages\django\urls\resolvers.py", line 526, in urlconf_module
    return import_module(self.urlconf_name)
  File "C:\Users\PHANI\AppData\Local\Programs\Python\Python36\lib\importlib\__init__.py", line 126, in import_module
    return _bootstrap._gcd_import(name[level:], package, level)
  File "<frozen importlib._bootstrap>", line 978, in _gcd_import
  File "<frozen importlib._bootstrap>", line 961, in _find_and_load
  File "<frozen importlib._bootstrap>", line 950, in _find_and_load_unlocked
  File "<frozen importlib._bootstrap>", line 655, in _load_unlocked
  File "<frozen importlib._bootstrap_external>", line 678, in exec_module
  File "<frozen importlib._bootstrap>", line 205, in _call_with_frames_removed
  File "C:\MAJOR PROJ\Adaptive_Hierarchical_Cyber_Attack_Detection\Adaptive_Hierarchical_Cyber_Attack_Detection\adaptive_hierarchical_cyber_attack_detection\adaptive_hierarchical_cyber_attack_detection\urls.py", line 20, in <module>
    from Service_Provider import views as serviceprovider
  File "C:\MAJOR PROJ\Adaptive_Hierarchical_Cyber_Attack_Detection\Adaptive_Hierarchical_Cyber_Attack_Detection\adaptive_hierarchical_cyber_attack_detection\Service_Provider\views.py", line 7, in <module>
    import xlwt
ModuleNotFoundError: No module named 'xlwt'

C:\MAJOR PROJ\Adaptive_Hierarchical_Cyber_Attack_Detection\Adaptive_Hierarchical_Cyber_Attack_Detection\adaptive_hierarchical_cyber_attack_detection>pip install xlwt
Collecting xlwt
  Downloading https://files.pythonhosted.org/packages/44/48/def306413b25c3d01753603b1a222a011b8621aed27cd7f89cbc27e6b0f4/xlwt-1.3.0-py2.py3-none-any.whl (99kB)
    100% |████████████████████████████████| 102kB 259kB/s
Installing collected packages: xlwt
Successfully installed xlwt-1.3.0
You are using pip version 9.0.1, however version 24.0 is available.
You should consider upgrading via the 'python -m pip install --upgrade pip' command.

C:\MAJOR PROJ\Adaptive_Hierarchical_Cyber_Attack_Detection\Adaptive_Hierarchical_Cyber_Attack_Detection\adaptive_hierarchical_cyber_attack_detection>python manage.py runserver
Performing system checks...

System check identified no issues (0 silenced).

You have 1 unapplied migration(s). Your project may not work properly until you apply the migrations for app(s): admin.
Run 'python manage.py migrate' to apply them.
February 25, 2024 - 16:59:22
Django version 2.1.7, using settings 'adaptive_hierarchical_cyber_attack_detection.settings'
Starting development server at http://127.0.0.1:8000/
Quit the server with CTRL-BREAK.
[25/Feb/2024 17:00:54] "GET / HTTP/1.1" 200 3052
[25/Feb/2024 17:00:54] "GET /static/login.jpg HTTP/1.1" 200 10119
Not Found: /images/icon.png
Not Found: /images/icon.png
[25/Feb/2024 17:00:55] "GET /images/icon.png HTTP/1.1" 404 4142
[25/Feb/2024 17:00:55] "GET /images/icon.png HTTP/1.1" 404 4142
[25/Feb/2024 17:00:55] "GET /static/bg.jpg HTTP/1.1" 200 193974
[25/Feb/2024 17:01:31] "GET /Register1/ HTTP/1.1" 200 7050
[25/Feb/2024 17:01:32] "GET /static/Register.jpg HTTP/1.1" 200 8045
Not Found: /favicon.ico
[25/Feb/2024 17:01:32] "GET /favicon.ico HTTP/1.1" 404 4130
[25/Feb/2024 17:02:36] "POST /Register1/ HTTP/1.1" 200 7073
[25/Feb/2024 17:03:20] "GET / HTTP/1.1" 200 3052
Not Found: /images/icon.png
[25/Feb/2024 17:03:20] "GET /images/icon.png HTTP/1.1" 404 4142
[25/Feb/2024 17:03:56] "GET / HTTP/1.1" 200 3052
[25/Feb/2024 17:03:56] "GET /static/login.jpg HTTP/1.1" 200 10119
[25/Feb/2024 17:03:56] "GET /static/bg.jpg HTTP/1.1" 200 193974
[25/Feb/2024 17:07:00] "POST / HTTP/1.1" 302 0
[25/Feb/2024 17:07:00] "GET /ViewYourProfile/ HTTP/1.1" 200 4323
Not Found: /ViewYourProfile/images/icon.png
[25/Feb/2024 17:07:01] "GET /ViewYourProfile/images/icon.png HTTP/1.1" 404 4190
[25/Feb/2024 17:07:56] "GET / HTTP/1.1" 200 3052
Not Found: /images/icon.png
[25/Feb/2024 17:07:57] "GET /images/icon.png HTTP/1.1" 404 4142
[25/Feb/2024 17:08:08] "GET /ViewYourProfile/ HTTP/1.1" 200 4323
[25/Feb/2024 17:08:10] "GET /predict_cyber_attack_type/ HTTP/1.1" 200 8832
Not Found: /predict_cyber_attack_type/images/icon.png
[25/Feb/2024 17:08:10] "GET /predict_cyber_attack_type/images/icon.png HTTP/1.1" 404 4220
[25/Feb/2024 17:08:53] "GET /predict_cyber_attack_type/ HTTP/1.1" 200 8832
RID
0         ci40330120
1         ci40330112
2         nc73770880
3         hv73118202
4         ci40330104
            ...
3417      pr71364903
3418      us6000i9ri
3419      tx2022ppcf
3420    ak022a7fg2u2
3421      pr71364893
Name: idnumber, Length: 3422, dtype: object
Label
0       0
1       1
2       1
3       1
4       0
       ..
3417    0
3418    1
3419    0
3420    1
3421    0
Name: label, Length: 3422, dtype: int64
SVM
54.45255474452555
CLASSIFICATION REPORT
              precision    recall  f1-score   support

           0       0.54      1.00      0.71       373
           1       0.00      0.00      0.00       312

    accuracy                           0.54       685
   macro avg       0.27      0.50      0.35       685
weighted avg       0.30      0.54      0.38       685

CONFUSION MATRIX
[[373   0]
 [312   0]]
Logistic Regression
ACCURACY
54.45255474452555
CLASSIFICATION REPORT
              precision    recall  f1-score   support

           0       0.54      1.00      0.71       373
           1       0.00      0.00      0.00       312

    accuracy                           0.54       685
   macro avg       0.27      0.50      0.35       685
weighted avg       0.30      0.54      0.38       685

CONFUSION MATRIX
[[373   0]
 [312   0]]
Random Forest Classifier
ACCURACY
54.45255474452555
CLASSIFICATION REPORT
              precision    recall  f1-score   support

           0       0.54      1.00      0.71       373
           1       0.00      0.00      0.00       312

    accuracy                           0.54       685
   macro avg       0.27      0.50      0.35       685
weighted avg       0.30      0.54      0.38       685

CONFUSION MATRIX
[[373   0]
 [312   0]]
KNeighborsClassifier
ACCURACY
54.45255474452555
CLASSIFICATION REPORT
              precision    recall  f1-score   support

           0       0.54      1.00      0.71       373
           1       0.00      0.00      0.00       312

    accuracy                           0.54       685
   macro avg       0.27      0.50      0.35       685
weighted avg       0.30      0.54      0.38       685

CONFUSION MATRIX
[[373   0]
 [312   0]]
Gradient Boosting Classifier
ACCURACY
54.45255474452555
CLASSIFICATION REPORT
              precision    recall  f1-score   support

           0       0.54      1.00      0.71       373
           1       0.00      0.00      0.00       312

    accuracy                           0.54       685
   macro avg       0.27      0.50      0.35       685
weighted avg       0.30      0.54      0.38       685

CONFUSION MATRIX
[[373   0]
 [312   0]]
No Cyber Attack Found
0
[25/Feb/2024 17:20:35] "POST /predict_cyber_attack_type/ HTTP/1.1" 200 8853
[25/Feb/2024 17:20:49] "GET /ViewYourProfile/ HTTP/1.1" 200 4323
Not Found: /ViewYourProfile/images/icon.png
[25/Feb/2024 17:20:50] "GET /ViewYourProfile/images/icon.png HTTP/1.1" 404 4190
Traceback (most recent call last):
  File "C:\Users\PHANI\AppData\Local\Programs\Python\Python36\lib\wsgiref\handlers.py", line 138, in run
    self.finish_response()
  File "C:\Users\PHANI\AppData\Local\Programs\Python\Python36\lib\wsgiref\handlers.py", line 180, in finish_response
    self.write(data)
  File "C:\Users\PHANI\AppData\Local\Programs\Python\Python36\lib\wsgiref\handlers.py", line 274, in write
    self.send_headers()
  File "C:\Users\PHANI\AppData\Local\Programs\Python\Python36\lib\wsgiref\handlers.py", line 332, in send_headers
    self.send_preamble()
  File "C:\Users\PHANI\AppData\Local\Programs\Python\Python36\lib\wsgiref\handlers.py", line 255, in send_preamble
    ('Date: %s\r\n' % format_date_time(time.time())).encode('iso-8859-1')
  File "C:\Users\PHANI\AppData\Local\Programs\Python\Python36\lib\wsgiref\handlers.py", line 453, in _write
    result = self.stdout.write(data)
  File "C:\Users\PHANI\AppData\Local\Programs\Python\Python36\lib\socketserver.py", line 775, in write
    self._sock.sendall(b)
ConnectionAbortedError: [WinError 10053] An established connection was aborted by the software in your host machine
[25/Feb/2024 17:20:50] "GET /ViewYourProfile/images/icon.png HTTP/1.1" 500 59
----------------------------------------
Exception happened during processing of request from ('127.0.0.1', 49735)
Traceback (most recent call last):
  File "C:\Users\PHANI\AppData\Local\Programs\Python\Python36\lib\wsgiref\handlers.py", line 138, in run
    self.finish_response()
  File "C:\Users\PHANI\AppData\Local\Programs\Python\Python36\lib\wsgiref\handlers.py", line 180, in finish_response
    self.write(data)
  File "C:\Users\PHANI\AppData\Local\Programs\Python\Python36\lib\wsgiref\handlers.py", line 274, in write
    self.send_headers()
  File "C:\Users\PHANI\AppData\Local\Programs\Python\Python36\lib\wsgiref\handlers.py", line 332, in send_headers
    self.send_preamble()
  File "C:\Users\PHANI\AppData\Local\Programs\Python\Python36\lib\wsgiref\handlers.py", line 255, in send_preamble
    ('Date: %s\r\n' % format_date_time(time.time())).encode('iso-8859-1')
  File "C:\Users\PHANI\AppData\Local\Programs\Python\Python36\lib\wsgiref\handlers.py", line 453, in _write
    result = self.stdout.write(data)
  File "C:\Users\PHANI\AppData\Local\Programs\Python\Python36\lib\socketserver.py", line 775, in write
    self._sock.sendall(b)
ConnectionAbortedError: [WinError 10053] An established connection was aborted by the software in your host machine

During handling of the above exception, another exception occurred:

Traceback (most recent call last):
  File "C:\Users\PHANI\AppData\Local\Programs\Python\Python36\lib\wsgiref\handlers.py", line 141, in run
    self.handle_error()
  File "C:\Users\PHANI\AppData\Local\Programs\Python\Python36\lib\site-packages\django\core\servers\basehttp.py", line 116, in handle_error
    super().handle_error()
  File "C:\Users\PHANI\AppData\Local\Programs\Python\Python36\lib\wsgiref\handlers.py", line 368, in handle_error
    self.finish_response()
  File "C:\Users\PHANI\AppData\Local\Programs\Python\Python36\lib\wsgiref\handlers.py", line 180, in finish_response
    self.write(data)
  File "C:\Users\PHANI\AppData\Local\Programs\Python\Python36\lib\wsgiref\handlers.py", line 274, in write
    self.send_headers()
  File "C:\Users\PHANI\AppData\Local\Programs\Python\Python36\lib\wsgiref\handlers.py", line 331, in send_headers
    if not self.origin_server or self.client_is_modern():
  File "C:\Users\PHANI\AppData\Local\Programs\Python\Python36\lib\wsgiref\handlers.py", line 344, in client_is_modern
    return self.environ['SERVER_PROTOCOL'].upper() != 'HTTP/0.9'
TypeError: 'NoneType' object is not subscriptable

During handling of the above exception, another exception occurred:

Traceback (most recent call last):
  File "C:\Users\PHANI\AppData\Local\Programs\Python\Python36\lib\socketserver.py", line 639, in process_request_thread
    self.finish_request(request, client_address)
  File "C:\Users\PHANI\AppData\Local\Programs\Python\Python36\lib\socketserver.py", line 361, in finish_request
    self.RequestHandlerClass(request, client_address, self)
  File "C:\Users\PHANI\AppData\Local\Programs\Python\Python36\lib\socketserver.py", line 696, in __init__
    self.handle()
  File "C:\Users\PHANI\AppData\Local\Programs\Python\Python36\lib\site-packages\django\core\servers\basehttp.py", line 171, in handle
    self.handle_one_request()
  File "C:\Users\PHANI\AppData\Local\Programs\Python\Python36\lib\site-packages\django\core\servers\basehttp.py", line 194, in handle_one_request
    handler.run(self.server.get_app())
  File "C:\Users\PHANI\AppData\Local\Programs\Python\Python36\lib\wsgiref\handlers.py", line 144, in run
    self.close()
  File "C:\Users\PHANI\AppData\Local\Programs\Python\Python36\lib\site-packages\django\core\servers\basehttp.py", line 111, in close
    super().close()
  File "C:\Users\PHANI\AppData\Local\Programs\Python\Python36\lib\wsgiref\simple_server.py", line 35, in close
    self.status.split(' ',1)[0], self.bytes_sent
AttributeError: 'NoneType' object has no attribute 'split'
----------------------------------------
[25/Feb/2024 17:21:04] "GET /serviceproviderlogin/ HTTP/1.1" 200 2504
Not Found: /serviceproviderlogin/images/icon.png
[25/Feb/2024 17:21:04] "GET /serviceproviderlogin/images/icon.png HTTP/1.1" 404 4205
[25/Feb/2024 17:21:34] "POST /serviceproviderlogin/ HTTP/1.1" 302 0
[25/Feb/2024 17:21:34] "GET /View_Remote_Users/ HTTP/1.1" 200 5909
Not Found: /View_Remote_Users/images/icon.png
[25/Feb/2024 17:21:35] "GET /View_Remote_Users/images/icon.png HTTP/1.1" 404 4196
RID
0             Jiangxi Sheng
1                       NaN
2                    Taipei
3                    Oregon
4                       NaN
               ...
3417    State of Tamil Nadu
3418            Beijing Shi
3419                    NaN
3420                    NaN
3421                 Quebec
Name: locale, Length: 3422, dtype: object
Label
0       0
1       1
2       1
3       1
4       0
       ..
3417    0
3418    1
3419    0
3420    1
3421    0
Name: label, Length: 3422, dtype: int64
SVM
51.97080291970803
CLASSIFICATION REPORT
              precision    recall  f1-score   support

           0       0.52      1.00      0.68       356
           1       0.00      0.00      0.00       329

    accuracy                           0.52       685
   macro avg       0.26      0.50      0.34       685
weighted avg       0.27      0.52      0.36       685

CONFUSION MATRIX
[[356   0]
 [329   0]]
Random Forest Classifier
ACCURACY
51.97080291970803
CLASSIFICATION REPORT
              precision    recall  f1-score   support

           0       0.52      1.00      0.68       356
           1       0.00      0.00      0.00       329

    accuracy                           0.52       685
   macro avg       0.26      0.50      0.34       685
weighted avg       0.27      0.52      0.36       685

CONFUSION MATRIX
[[356   0]
 [329   0]]
KNeighborsClassifier
ACCURACY
51.97080291970803
CLASSIFICATION REPORT
              precision    recall  f1-score   support

           0       0.52      1.00      0.68       356
           1       0.00      0.00      0.00       329

    accuracy                           0.52       685
   macro avg       0.26      0.50      0.34       685
weighted avg       0.27      0.52      0.36       685

CONFUSION MATRIX
[[356   0]
 [329   0]]
Gradient Boosting Classifier
ACCURACY
51.97080291970803
CLASSIFICATION REPORT
              precision    recall  f1-score   support

           0       0.52      1.00      0.68       356
           1       0.00      0.00      0.00       329

    accuracy                           0.52       685
   macro avg       0.26      0.50      0.34       685
weighted avg       0.27      0.52      0.36       685

CONFUSION MATRIX
[[356   0]
 [329   0]]
[25/Feb/2024 17:21:48] "GET /Train_Test_DataSets/ HTTP/1.1" 200 5532
Not Found: /Train_Test_DataSets/images/icon.png
[25/Feb/2024 17:21:49] "GET /Train_Test_DataSets/images/icon.png HTTP/1.1" 404 4202
[25/Feb/2024 17:21:53] "GET /likeschart/bar HTTP/1.1" 200 3495
[25/Feb/2024 17:22:09] "GET /charts1/line HTTP/1.1" 200 3593
[25/Feb/2024 17:22:21] "GET /charts1/pie HTTP/1.1" 200 3592
[25/Feb/2024 17:22:35] "GET /View_Prediction_Of_Cyber_Attack_Type/ HTTP/1.1" 200 13797
Not Found: /View_Prediction_Of_Cyber_Attack_Type/images/icon.png
[25/Feb/2024 17:22:36] "GET /View_Prediction_Of_Cyber_Attack_Type/images/icon.png HTTP/1.1" 404 4253
No Cyber Attack Found
Cyber Attack Found
[25/Feb/2024 17:23:56] "GET /View_Prediction_Of_Cyber_Attack_Type_Ratio/ HTTP/1.1" 200 4579
Not Found: /View_Prediction_Of_Cyber_Attack_Type_Ratio/images/icon.png
[25/Feb/2024 17:23:57] "GET /View_Prediction_Of_Cyber_Attack_Type_Ratio/images/icon.png HTTP/1.1" 404 4271
[25/Feb/2024 17:24:06] "GET /Download_Trained_DataSets/ HTTP/1.1" 200 5632
[25/Feb/2024 17:24:12] "GET /charts/line HTTP/1.1" 200 3474
[25/Feb/2024 17:25:31] "GET /charts/pie HTTP/1.1" 200 3473
[25/Feb/2024 17:25:36] "GET /View_Remote_Users/ HTTP/1.1" 200 5909
Not Found: /View_Remote_Users/images/icon.png
[25/Feb/2024 17:25:36] "GET /View_Remote_Users/images/icon.png HTTP/1.1" 404 4196
Traceback (most recent call last):
  File "C:\Users\PHANI\AppData\Local\Programs\Python\Python36\lib\wsgiref\handlers.py", line 138, in run
    self.finish_response()
  File "C:\Users\PHANI\AppData\Local\Programs\Python\Python36\lib\wsgiref\handlers.py", line 180, in finish_response
    self.write(data)
  File "C:\Users\PHANI\AppData\Local\Programs\Python\Python36\lib\wsgiref\handlers.py", line 274, in write
    self.send_headers()
  File "C:\Users\PHANI\AppData\Local\Programs\Python\Python36\lib\wsgiref\handlers.py", line 332, in send_headers
    self.send_preamble()
  File "C:\Users\PHANI\AppData\Local\Programs\Python\Python36\lib\wsgiref\handlers.py", line 255, in send_preamble
    ('Date: %s\r\n' % format_date_time(time.time())).encode('iso-8859-1')
  File "C:\Users\PHANI\AppData\Local\Programs\Python\Python36\lib\wsgiref\handlers.py", line 453, in _write
    result = self.stdout.write(data)
  File "C:\Users\PHANI\AppData\Local\Programs\Python\Python36\lib\socketserver.py", line 775, in write
    self._sock.sendall(b)
ConnectionAbortedError: [WinError 10053] An established connection was aborted by the software in your host machine
[25/Feb/2024 17:25:36] "GET /View_Remote_Users/images/icon.png HTTP/1.1" 500 59
----------------------------------------
Exception happened during processing of request from ('127.0.0.1', 49746)
Traceback (most recent call last):
  File "C:\Users\PHANI\AppData\Local\Programs\Python\Python36\lib\wsgiref\handlers.py", line 138, in run
    self.finish_response()
  File "C:\Users\PHANI\AppData\Local\Programs\Python\Python36\lib\wsgiref\handlers.py", line 180, in finish_response
    self.write(data)
  File "C:\Users\PHANI\AppData\Local\Programs\Python\Python36\lib\wsgiref\handlers.py", line 274, in write
    self.send_headers()
  File "C:\Users\PHANI\AppData\Local\Programs\Python\Python36\lib\wsgiref\handlers.py", line 332, in send_headers
    self.send_preamble()
  File "C:\Users\PHANI\AppData\Local\Programs\Python\Python36\lib\wsgiref\handlers.py", line 255, in send_preamble
    ('Date: %s\r\n' % format_date_time(time.time())).encode('iso-8859-1')
  File "C:\Users\PHANI\AppData\Local\Programs\Python\Python36\lib\wsgiref\handlers.py", line 453, in _write
    result = self.stdout.write(data)
  File "C:\Users\PHANI\AppData\Local\Programs\Python\Python36\lib\socketserver.py", line 775, in write
    self._sock.sendall(b)
ConnectionAbortedError: [WinError 10053] An established connection was aborted by the software in your host machine

During handling of the above exception, another exception occurred:

Traceback (most recent call last):
  File "C:\Users\PHANI\AppData\Local\Programs\Python\Python36\lib\wsgiref\handlers.py", line 141, in run
    self.handle_error()
  File "C:\Users\PHANI\AppData\Local\Programs\Python\Python36\lib\site-packages\django\core\servers\basehttp.py", line 116, in handle_error
    super().handle_error()
  File "C:\Users\PHANI\AppData\Local\Programs\Python\Python36\lib\wsgiref\handlers.py", line 368, in handle_error
    self.finish_response()
  File "C:\Users\PHANI\AppData\Local\Programs\Python\Python36\lib\wsgiref\handlers.py", line 180, in finish_response
    self.write(data)
  File "C:\Users\PHANI\AppData\Local\Programs\Python\Python36\lib\wsgiref\handlers.py", line 274, in write
    self.send_headers()
  File "C:\Users\PHANI\AppData\Local\Programs\Python\Python36\lib\wsgiref\handlers.py", line 331, in send_headers
    if not self.origin_server or self.client_is_modern():
  File "C:\Users\PHANI\AppData\Local\Programs\Python\Python36\lib\wsgiref\handlers.py", line 344, in client_is_modern
    return self.environ['SERVER_PROTOCOL'].upper() != 'HTTP/0.9'
TypeError: 'NoneType' object is not subscriptable

During handling of the above exception, another exception occurred:

Traceback (most recent call last):
  File "C:\Users\PHANI\AppData\Local\Programs\Python\Python36\lib\socketserver.py", line 639, in process_request_thread
    self.finish_request(request, client_address)
  File "C:\Users\PHANI\AppData\Local\Programs\Python\Python36\lib\socketserver.py", line 361, in finish_request
    self.RequestHandlerClass(request, client_address, self)
  File "C:\Users\PHANI\AppData\Local\Programs\Python\Python36\lib\socketserver.py", line 696, in __init__
    self.handle()
  File "C:\Users\PHANI\AppData\Local\Programs\Python\Python36\lib\site-packages\django\core\servers\basehttp.py", line 171, in handle
    self.handle_one_request()
  File "C:\Users\PHANI\AppData\Local\Programs\Python\Python36\lib\site-packages\django\core\servers\basehttp.py", line 194, in handle_one_request
    handler.run(self.server.get_app())
  File "C:\Users\PHANI\AppData\Local\Programs\Python\Python36\lib\wsgiref\handlers.py", line 144, in run
    self.close()
  File "C:\Users\PHANI\AppData\Local\Programs\Python\Python36\lib\site-packages\django\core\servers\basehttp.py", line 111, in close
    super().close()
  File "C:\Users\PHANI\AppData\Local\Programs\Python\Python36\lib\wsgiref\simple_server.py", line 35, in close
    self.status.split(' ',1)[0], self.bytes_sent
AttributeError: 'NoneType' object has no attribute 'split'
----------------------------------------
[25/Feb/2024 17:51:18] "GET /charts/line HTTP/1.1" 200 3474
RID
0             Jiangxi Sheng
1                       NaN
2                    Taipei
3                    Oregon
4                       NaN
               ...
3417    State of Tamil Nadu
3418            Beijing Shi
3419                    NaN
3420                    NaN
3421                 Quebec
Name: locale, Length: 3422, dtype: object
Label
0       0
1       1
2       1
3       1
4       0
       ..
3417    0
3418    1
3419    0
3420    1
3421    0
Name: label, Length: 3422, dtype: int64
RID
0             Jiangxi Sheng
1                       NaN
2                    Taipei
3                    Oregon
4                       NaN
               ...
3417    State of Tamil Nadu
3418            Beijing Shi
3419                    NaN
3420                    NaN
3421                 Quebec
Name: locale, Length: 3422, dtype: objectSVM

Label
0       0
1       1
2       1
3       1
4       0
       ..
3417    0
3418    1
3419    0
3420    1
3421    0
Name: label, Length: 3422, dtype: int64
53.284671532846716
CLASSIFICATION REPORT
[25/Feb/2024 17:51:34] "GET / HTTP/1.1" 200 3052
              precision    recall  f1-score   support

           0       0.53      1.00      0.70       365
           1       0.00      0.00      0.00       320

    accuracy                           0.53       685
   macro avg       0.27      0.50      0.35       685
weighted avg       0.28      0.53      0.37       685

CONFUSION MATRIX
[[365   0]
 [320   0]]
Random Forest Classifier
[25/Feb/2024 17:51:34] "GET /static/login.jpg HTTP/1.1" 200 8192
Traceback (most recent call last):
  File "C:\Users\PHANI\AppData\Local\Programs\Python\Python36\lib\wsgiref\handlers.py", line 138, in run
    self.finish_response()
  File "C:\Users\PHANI\AppData\Local\Programs\Python\Python36\lib\wsgiref\handlers.py", line 180, in finish_response
    self.write(data)
  File "C:\Users\PHANI\AppData\Local\Programs\Python\Python36\lib\wsgiref\handlers.py", line 274, in write
    self.send_headers()
  File "C:\Users\PHANI\AppData\Local\Programs\Python\Python36\lib\wsgiref\handlers.py", line 332, in send_headers
    self.send_preamble()
  File "C:\Users\PHANI\AppData\Local\Programs\Python\Python36\lib\wsgiref\handlers.py", line 255, in send_preamble
    ('Date: %s\r\n' % format_date_time(time.time())).encode('iso-8859-1')
  File "C:\Users\PHANI\AppData\Local\Programs\Python\Python36\lib\wsgiref\handlers.py", line 453, in _write
    result = self.stdout.write(data)
  File "C:\Users\PHANI\AppData\Local\Programs\Python\Python36\lib\socketserver.py", line 775, in write
    self._sock.sendall(b)
ConnectionAbortedError: [WinError 10053] An established connection was aborted by the software in your host machine
[25/Feb/2024 17:51:35] "GET /static/login.jpg HTTP/1.1" 500 59
----------------------------------------
Exception happened during processing of request from ('127.0.0.1', 57357)
Not Found: /images/icon.png
Traceback (most recent call last):
  File "C:\Users\PHANI\AppData\Local\Programs\Python\Python36\lib\wsgiref\handlers.py", line 138, in run
    self.finish_response()
  File "C:\Users\PHANI\AppData\Local\Programs\Python\Python36\lib\wsgiref\handlers.py", line 180, in finish_response
    self.write(data)
  File "C:\Users\PHANI\AppData\Local\Programs\Python\Python36\lib\wsgiref\handlers.py", line 274, in write
    self.send_headers()
  File "C:\Users\PHANI\AppData\Local\Programs\Python\Python36\lib\wsgiref\handlers.py", line 332, in send_headers
    self.send_preamble()
  File "C:\Users\PHANI\AppData\Local\Programs\Python\Python36\lib\wsgiref\handlers.py", line 255, in send_preamble
    ('Date: %s\r\n' % format_date_time(time.time())).encode('iso-8859-1')
  File "C:\Users\PHANI\AppData\Local\Programs\Python\Python36\lib\wsgiref\handlers.py", line 453, in _write
    result = self.stdout.write(data)
[25/Feb/2024 17:51:35] "GET /images/icon.png HTTP/1.1" 404 4142
  File "C:\Users\PHANI\AppData\Local\Programs\Python\Python36\lib\socketserver.py", line 775, in write
    self._sock.sendall(b)
ConnectionAbortedError: [WinError 10053] An established connection was aborted by the software in your host machine

During handling of the above exception, another exception occurred:

Traceback (most recent call last):
  File "C:\Users\PHANI\AppData\Local\Programs\Python\Python36\lib\wsgiref\handlers.py", line 141, in run
    self.handle_error()
  File "C:\Users\PHANI\AppData\Local\Programs\Python\Python36\lib\site-packages\django\core\servers\basehttp.py", line 116, in handle_error
    super().handle_error()
  File "C:\Users\PHANI\AppData\Local\Programs\Python\Python36\lib\wsgiref\handlers.py", line 368, in handle_error
    self.finish_response()
  File "C:\Users\PHANI\AppData\Local\Programs\Python\Python36\lib\wsgiref\handlers.py", line 180, in finish_response
    self.write(data)
  File "C:\Users\PHANI\AppData\Local\Programs\Python\Python36\lib\wsgiref\handlers.py", line 274, in write
    self.send_headers()
  File "C:\Users\PHANI\AppData\Local\Programs\Python\Python36\lib\wsgiref\handlers.py", line 331, in send_headers
    if not self.origin_server or self.client_is_modern():
  File "C:\Users\PHANI\AppData\Local\Programs\Python\Python36\lib\wsgiref\handlers.py", line 344, in client_is_modern
    return self.environ['SERVER_PROTOCOL'].upper() != 'HTTP/0.9'
TypeError: 'NoneType' object is not subscriptable

During handling of the above exception, another exception occurred:

Traceback (most recent call last):
  File "C:\Users\PHANI\AppData\Local\Programs\Python\Python36\lib\socketserver.py", line 639, in process_request_thread
    self.finish_request(request, client_address)
  File "C:\Users\PHANI\AppData\Local\Programs\Python\Python36\lib\socketserver.py", line 361, in finish_request
    self.RequestHandlerClass(request, client_address, self)
  File "C:\Users\PHANI\AppData\Local\Programs\Python\Python36\lib\socketserver.py", line 696, in __init__
    self.handle()
  File "C:\Users\PHANI\AppData\Local\Programs\Python\Python36\lib\site-packages\django\core\servers\basehttp.py", line 171, in handle
    self.handle_one_request()
  File "C:\Users\PHANI\AppData\Local\Programs\Python\Python36\lib\site-packages\django\core\servers\basehttp.py", line 194, in handle_one_request
    handler.run(self.server.get_app())
  File "C:\Users\PHANI\AppData\Local\Programs\Python\Python36\lib\wsgiref\handlers.py", line 144, in run
    self.close()
  File "C:\Users\PHANI\AppData\Local\Programs\Python\Python36\lib\site-packages\django\core\servers\basehttp.py", line 111, in close
    super().close()
  File "C:\Users\PHANI\AppData\Local\Programs\Python\Python36\lib\wsgiref\simple_server.py", line 35, in close
    self.status.split(' ',1)[0], self.bytes_sent
AttributeError: 'NoneType' object has no attribute 'split'
----------------------------------------
[25/Feb/2024 17:51:38] "POST / HTTP/1.1" 302 0
[25/Feb/2024 17:51:38] "GET /ViewYourProfile/ HTTP/1.1" 200 4323
SVM
ACCURACY
53.284671532846716
CLASSIFICATION REPORT
              precision    recall  f1-score   support

           0       0.53      1.00      0.70       365
           1       0.00      0.00      0.00       320

    accuracy                           0.53       685
   macro avg       0.27      0.50      0.35       685
weighted avg       0.28      0.53      0.37       685

CONFUSION MATRIX
[[365   0]
 [320   0]]
KNeighborsClassifier
54.16058394160584
CLASSIFICATION REPORT
              precision    recall  f1-score   support

           0       0.54      1.00      0.70       371
           1       0.00      0.00      0.00       314

    accuracy                           0.54       685
   macro avg       0.27      0.50      0.35       685
weighted avg       0.29      0.54      0.38       685

CONFUSION MATRIX
[[371   0]
 [314   0]]
Random Forest Classifier
ACCURACY
53.284671532846716
CLASSIFICATION REPORT
              precision    recall  f1-score   support

           0       0.53      1.00      0.70       365
           1       0.00      0.00      0.00       320

    accuracy                           0.53       685
   macro avg       0.27      0.50      0.35       685
weighted avg       0.28      0.53      0.37       685

CONFUSION MATRIX
[[365   0]
 [320   0]]
Gradient Boosting Classifier
ACCURACY
54.16058394160584
CLASSIFICATION REPORT
              precision    recall  f1-score   support

           0       0.54      1.00      0.70       371
           1       0.00      0.00      0.00       314

    accuracy                           0.54       685
   macro avg       0.27      0.50      0.35       685
weighted avg       0.29      0.54      0.38       685

CONFUSION MATRIX
[[371   0]
 [314   0]]
KNeighborsClassifier
ACCURACY
53.284671532846716
CLASSIFICATION REPORT
              precision    recall  f1-score   support

           0       0.53      1.00      0.70       365
           1       0.00      0.00      0.00       320

    accuracy                           0.53       685
   macro avg       0.27      0.50      0.35       685
weighted avg       0.28      0.53      0.37       685

CONFUSION MATRIX
[[365   0]
 [320   0]]
[25/Feb/2024 17:51:40] "GET /Train_Test_DataSets/ HTTP/1.1" 200 6483
Traceback (most recent call last):
  File "C:\Users\PHANI\AppData\Local\Programs\Python\Python36\lib\wsgiref\handlers.py", line 138, in run
    self.finish_response()
  File "C:\Users\PHANI\AppData\Local\Programs\Python\Python36\lib\wsgiref\handlers.py", line 180, in finish_response
    self.write(data)
  File "C:\Users\PHANI\AppData\Local\Programs\Python\Python36\lib\wsgiref\handlers.py", line 274, in write
    self.send_headers()
  File "C:\Users\PHANI\AppData\Local\Programs\Python\Python36\lib\wsgiref\handlers.py", line 332, in send_headers
    self.send_preamble()
  File "C:\Users\PHANI\AppData\Local\Programs\Python\Python36\lib\wsgiref\handlers.py", line 255, in send_preamble
    ('Date: %s\r\n' % format_date_time(time.time())).encode('iso-8859-1')
  File "C:\Users\PHANI\AppData\Local\Programs\Python\Python36\lib\wsgiref\handlers.py", line 453, in _write
    result = self.stdout.write(data)
  File "C:\Users\PHANI\AppData\Local\Programs\Python\Python36\lib\socketserver.py", line 775, in write
    self._sock.sendall(b)
ConnectionAbortedError: [WinError 10053] An established connection was aborted by the software in your host machine
[25/Feb/2024 17:51:40] "GET /Train_Test_DataSets/ HTTP/1.1" 500 59
----------------------------------------
Exception happened during processing of request from ('127.0.0.1', 57341)
Traceback (most recent call last):
  File "C:\Users\PHANI\AppData\Local\Programs\Python\Python36\lib\wsgiref\handlers.py", line 138, in run
    self.finish_response()
  File "C:\Users\PHANI\AppData\Local\Programs\Python\Python36\lib\wsgiref\handlers.py", line 180, in finish_response
    self.write(data)
  File "C:\Users\PHANI\AppData\Local\Programs\Python\Python36\lib\wsgiref\handlers.py", line 274, in write
    self.send_headers()
  File "C:\Users\PHANI\AppData\Local\Programs\Python\Python36\lib\wsgiref\handlers.py", line 332, in send_headers
    self.send_preamble()
  File "C:\Users\PHANI\AppData\Local\Programs\Python\Python36\lib\wsgiref\handlers.py", line 255, in send_preamble
    ('Date: %s\r\n' % format_date_time(time.time())).encode('iso-8859-1')
  File "C:\Users\PHANI\AppData\Local\Programs\Python\Python36\lib\wsgiref\handlers.py", line 453, in _write
    result = self.stdout.write(data)
  File "C:\Users\PHANI\AppData\Local\Programs\Python\Python36\lib\socketserver.py", line 775, in write
    self._sock.sendall(b)
ConnectionAbortedError: [WinError 10053] An established connection was aborted by the software in your host machine

During handling of the above exception, another exception occurred:

Traceback (most recent call last):
  File "C:\Users\PHANI\AppData\Local\Programs\Python\Python36\lib\wsgiref\handlers.py", line 141, in run
    self.handle_error()
  File "C:\Users\PHANI\AppData\Local\Programs\Python\Python36\lib\site-packages\django\core\servers\basehttp.py", line 116, in handle_error
    super().handle_error()
  File "C:\Users\PHANI\AppData\Local\Programs\Python\Python36\lib\wsgiref\handlers.py", line 368, in handle_error
    self.finish_response()
  File "C:\Users\PHANI\AppData\Local\Programs\Python\Python36\lib\wsgiref\handlers.py", line 180, in finish_response
    self.write(data)
  File "C:\Users\PHANI\AppData\Local\Programs\Python\Python36\lib\wsgiref\handlers.py", line 274, in write
    self.send_headers()
  File "C:\Users\PHANI\AppData\Local\Programs\Python\Python36\lib\wsgiref\handlers.py", line 331, in send_headers
    if not self.origin_server or self.client_is_modern():
  File "C:\Users\PHANI\AppData\Local\Programs\Python\Python36\lib\wsgiref\handlers.py", line 344, in client_is_modern
    return self.environ['SERVER_PROTOCOL'].upper() != 'HTTP/0.9'
TypeError: 'NoneType' object is not subscriptable

During handling of the above exception, another exception occurred:

Traceback (most recent call last):
  File "C:\Users\PHANI\AppData\Local\Programs\Python\Python36\lib\socketserver.py", line 639, in process_request_thread
    self.finish_request(request, client_address)
  File "C:\Users\PHANI\AppData\Local\Programs\Python\Python36\lib\socketserver.py", line 361, in finish_request
    self.RequestHandlerClass(request, client_address, self)
  File "C:\Users\PHANI\AppData\Local\Programs\Python\Python36\lib\socketserver.py", line 696, in __init__
    self.handle()
  File "C:\Users\PHANI\AppData\Local\Programs\Python\Python36\lib\site-packages\django\core\servers\basehttp.py", line 171, in handle
    self.handle_one_request()
  File "C:\Users\PHANI\AppData\Local\Programs\Python\Python36\lib\site-packages\django\core\servers\basehttp.py", line 194, in handle_one_request
    handler.run(self.server.get_app())
  File "C:\Users\PHANI\AppData\Local\Programs\Python\Python36\lib\wsgiref\handlers.py", line 144, in run
    self.close()
  File "C:\Users\PHANI\AppData\Local\Programs\Python\Python36\lib\site-packages\django\core\servers\basehttp.py", line 111, in close
    super().close()
  File "C:\Users\PHANI\AppData\Local\Programs\Python\Python36\lib\wsgiref\simple_server.py", line 35, in close
    self.status.split(' ',1)[0], self.bytes_sent
AttributeError: 'NoneType' object has no attribute 'split'
----------------------------------------
ACCURACY
45.839416058394164
CLASSIFICATION REPORT
              precision    recall  f1-score   support

           0       0.00      0.00      0.00       371
           1       0.46      1.00      0.63       314

    accuracy                           0.46       685
   macro avg       0.23      0.50      0.31       685
weighted avg       0.21      0.46      0.29       685

CONFUSION MATRIX
[[  0 371]
 [  0 314]]
Gradient Boosting Classifier
ACCURACY
54.16058394160584
CLASSIFICATION REPORT
              precision    recall  f1-score   support

           0       0.54      1.00      0.70       371
           1       0.00      0.00      0.00       314

    accuracy                           0.54       685
   macro avg       0.27      0.50      0.35       685
weighted avg       0.29      0.54      0.38       685

CONFUSION MATRIX
[[371   0]
 [314   0]]
[25/Feb/2024 17:51:41] "GET /Train_Test_DataSets/ HTTP/1.1" 200 7452
[25/Feb/2024 17:51:53] "GET /predict_cyber_attack_type/ HTTP/1.1" 200 8832
Not Found: /predict_cyber_attack_type/images/icon.png
[25/Feb/2024 17:51:54] "GET /predict_cyber_attack_type/images/icon.png HTTP/1.1" 404 4220
Traceback (most recent call last):
  File "C:\Users\PHANI\AppData\Local\Programs\Python\Python36\lib\wsgiref\handlers.py", line 138, in run
    self.finish_response()
  File "C:\Users\PHANI\AppData\Local\Programs\Python\Python36\lib\wsgiref\handlers.py", line 180, in finish_response
    self.write(data)
  File "C:\Users\PHANI\AppData\Local\Programs\Python\Python36\lib\wsgiref\handlers.py", line 274, in write
    self.send_headers()
  File "C:\Users\PHANI\AppData\Local\Programs\Python\Python36\lib\wsgiref\handlers.py", line 332, in send_headers
    self.send_preamble()
  File "C:\Users\PHANI\AppData\Local\Programs\Python\Python36\lib\wsgiref\handlers.py", line 255, in send_preamble
    ('Date: %s\r\n' % format_date_time(time.time())).encode('iso-8859-1')
  File "C:\Users\PHANI\AppData\Local\Programs\Python\Python36\lib\wsgiref\handlers.py", line 453, in _write
    result = self.stdout.write(data)
  File "C:\Users\PHANI\AppData\Local\Programs\Python\Python36\lib\socketserver.py", line 775, in write
    self._sock.sendall(b)
ConnectionAbortedError: [WinError 10053] An established connection was aborted by the software in your host machine
[25/Feb/2024 17:51:54] "GET /predict_cyber_attack_type/images/icon.png HTTP/1.1" 500 59
----------------------------------------
Exception happened during processing of request from ('127.0.0.1', 57353)
Traceback (most recent call last):
  File "C:\Users\PHANI\AppData\Local\Programs\Python\Python36\lib\wsgiref\handlers.py", line 138, in run
    self.finish_response()
  File "C:\Users\PHANI\AppData\Local\Programs\Python\Python36\lib\wsgiref\handlers.py", line 180, in finish_response
    self.write(data)
  File "C:\Users\PHANI\AppData\Local\Programs\Python\Python36\lib\wsgiref\handlers.py", line 274, in write
    self.send_headers()
  File "C:\Users\PHANI\AppData\Local\Programs\Python\Python36\lib\wsgiref\handlers.py", line 332, in send_headers
    self.send_preamble()
  File "C:\Users\PHANI\AppData\Local\Programs\Python\Python36\lib\wsgiref\handlers.py", line 255, in send_preamble
    ('Date: %s\r\n' % format_date_time(time.time())).encode('iso-8859-1')
  File "C:\Users\PHANI\AppData\Local\Programs\Python\Python36\lib\wsgiref\handlers.py", line 453, in _write
    result = self.stdout.write(data)
  File "C:\Users\PHANI\AppData\Local\Programs\Python\Python36\lib\socketserver.py", line 775, in write
    self._sock.sendall(b)
ConnectionAbortedError: [WinError 10053] An established connection was aborted by the software in your host machine

During handling of the above exception, another exception occurred:

Traceback (most recent call last):
  File "C:\Users\PHANI\AppData\Local\Programs\Python\Python36\lib\wsgiref\handlers.py", line 141, in run
    self.handle_error()
  File "C:\Users\PHANI\AppData\Local\Programs\Python\Python36\lib\site-packages\django\core\servers\basehttp.py", line 116, in handle_error
    super().handle_error()
  File "C:\Users\PHANI\AppData\Local\Programs\Python\Python36\lib\wsgiref\handlers.py", line 368, in handle_error
    self.finish_response()
  File "C:\Users\PHANI\AppData\Local\Programs\Python\Python36\lib\wsgiref\handlers.py", line 180, in finish_response
    self.write(data)
  File "C:\Users\PHANI\AppData\Local\Programs\Python\Python36\lib\wsgiref\handlers.py", line 274, in write
    self.send_headers()
  File "C:\Users\PHANI\AppData\Local\Programs\Python\Python36\lib\wsgiref\handlers.py", line 331, in send_headers
    if not self.origin_server or self.client_is_modern():
  File "C:\Users\PHANI\AppData\Local\Programs\Python\Python36\lib\wsgiref\handlers.py", line 344, in client_is_modern
    return self.environ['SERVER_PROTOCOL'].upper() != 'HTTP/0.9'
TypeError: 'NoneType' object is not subscriptable

During handling of the above exception, another exception occurred:

Traceback (most recent call last):
  File "C:\Users\PHANI\AppData\Local\Programs\Python\Python36\lib\socketserver.py", line 639, in process_request_thread
    self.finish_request(request, client_address)
  File "C:\Users\PHANI\AppData\Local\Programs\Python\Python36\lib\socketserver.py", line 361, in finish_request
    self.RequestHandlerClass(request, client_address, self)
  File "C:\Users\PHANI\AppData\Local\Programs\Python\Python36\lib\socketserver.py", line 696, in __init__
    self.handle()
  File "C:\Users\PHANI\AppData\Local\Programs\Python\Python36\lib\site-packages\django\core\servers\basehttp.py", line 171, in handle
    self.handle_one_request()
  File "C:\Users\PHANI\AppData\Local\Programs\Python\Python36\lib\site-packages\django\core\servers\basehttp.py", line 194, in handle_one_request
    handler.run(self.server.get_app())
  File "C:\Users\PHANI\AppData\Local\Programs\Python\Python36\lib\wsgiref\handlers.py", line 144, in run
    self.close()
  File "C:\Users\PHANI\AppData\Local\Programs\Python\Python36\lib\site-packages\django\core\servers\basehttp.py", line 111, in close
    super().close()
  File "C:\Users\PHANI\AppData\Local\Programs\Python\Python36\lib\wsgiref\simple_server.py", line 35, in close
    self.status.split(' ',1)[0], self.bytes_sent
AttributeError: 'NoneType' object has no attribute 'split'
----------------------------------------


